<?xml version="1.0" ?>
<sdf version="1.8">
  <world name="maze_world">
    <plugin filename="gz-sim-physics-system" name="gz::sim::systems::Physics"/>
    <plugin filename="gz-sim-scene-broadcaster-system" name="gz::sim::systems::SceneBroadcaster"/>
    <plugin filename="gz-sim-sensors-system" name="gz::sim::systems::Sensors">
      <render_engine>ogre</render_engine>
    </plugin>

    <light type="directional" name="sun">
      <cast_shadows>true</cast_shadows>
      <pose>0 0 10 0 0 0</pose>
      <diffuse>0.8 0.8 0.8 1</diffuse>
      <specular>0.2 0.2 0.2 1</specular>
      <direction>-0.5 0.1 -0.9</direction>
    </light>
    
    <model name="ground_plane">
      <static>true</static>
      <link name="link">
        <collision name="collision">
          <geometry><plane><normal>0 0 1</normal><size>100 100</size></plane></geometry>
        </collision>
        <visual name="visual">
          <geometry><plane><normal>0 0 1</normal><size>100 100</size></plane></geometry>
          <material><ambient>0.8 0.8 0.8 1</ambient></material>
        </visual>
      </link>
    </model>

    <model name="maze_walls">
      <static>true</static>
      <link name="wall1"><pose>3 0 0.5 0 0 0</pose><collision name="c"><geometry><box><size>0.2 6 1</size></box></geometry></collision><visual name="v"><geometry><box><size>0.2 6 1</size></box></geometry></visual></link>
      <link name="wall2"><pose>-3 0 0.5 0 0 0</pose><collision name="c"><geometry><box><size>0.2 6 1</size></box></geometry></collision><visual name="v"><geometry><box><size>0.2 6 1</size></box></geometry></visual></link>
      <link name="wall3"><pose>0 3 0.5 0 0 0</pose><collision name="c"><geometry><box><size>6.2 0.2 1</size></box></geometry></collision><visual name="v"><geometry><box><size>6.2 0.2 1</size></box></geometry></visual></link>
      <link name="obstacle"><pose>0 1 0.5 0 0 0</pose><collision name="c"><geometry><box><size>2 2 1</size></box></geometry></collision><visual name="v"><geometry><box><size>2 2 1</size></box></geometry></visual></link>
    </model>

    <model name="diff_robot">
      <pose>0 -2 0.15 0 0 1.5707</pose>
      
      <link name="chassis">
        <pose>0 0 0.1 0 0 0</pose>
        <inertial>
          <mass>1.0</mass>
          <inertia>
            <ixx>0.01</ixx><ixy>0</ixy><ixz>0</ixz>
            <iyy>0.01</iyy><iyz>0</iyz><izz>0.01</izz>
          </inertia>
        </inertial>
        <collision name="collision"><geometry><box><size>0.25 0.2 0.1</size></box></geometry></collision>
        <visual name="visual"><geometry><box><size>0.25 0.2 0.1</size></box></geometry><material><ambient>0 0 1 1</ambient></material></visual>
      </link>

      <link name="left_wheel">
        <pose>0.05 0.12 0.1 -1.5707 0 0</pose>
        <collision name="collision">
          <geometry><cylinder><radius>0.1</radius><length>0.04</length></cylinder></geometry>
          <surface><friction><ode><mu>10.0</mu><mu2>10.0</mu2></ode></friction></surface>
        </collision>
        <visual name="visual"><geometry><cylinder><radius>0.1</radius><length>0.04</length></cylinder></geometry></visual>
      </link>

      <link name="right_wheel">
        <pose>0.05 -0.12 0.1 -1.5707 0 0</pose>
        <collision name="collision">
          <geometry><cylinder><radius>0.1</radius><length>0.04</length></cylinder></geometry>
          <surface><friction><ode><mu>10.0</mu><mu2>10.0</mu2></ode></friction></surface>
        </collision>
        <visual name="visual"><geometry><cylinder><radius>0.1</radius><length>0.04</length></cylinder></geometry></visual>
      </link>

      <link name="caster">
        <pose>-0.1 0 0.05 0 0 0</pose>
        <collision name="collision">
          <geometry><sphere><radius>0.05</radius></sphere></geometry>
          <surface><friction><ode><mu>0.0</mu><mu2>0.0</mu2></ode></friction></surface>
        </collision>
        <visual name="visual"><geometry><sphere><radius>0.05</radius></sphere></geometry></visual>
      </link>

      <link name="lidar_link">
        <pose>0.1 0 0.2 0 0 0</pose>
        <sensor name="lidar_sensor" type="lidar">
          <topic>/scan</topic>
          <update_rate>10</update_rate>
          <ray>
            <scan><horizontal><samples>360</samples><resolution>1</resolution><min_angle>-3.14159</min_angle><max_angle>3.14159</max_angle></horizontal></scan>
            <range><min>0.12</min><max>10.0</max></range>
          </ray>
          <always_on>1</always_on>
          <visualize>true</visualize>
        </sensor>
        <visual name="visual"><geometry><cylinder><radius>0.04</radius><length>0.05</length></cylinder></geometry><material><ambient>1 0 0 1</ambient></material></visual>
      </link>

      <joint name="left_wheel_joint" type="revolute"><parent>chassis</parent><child>left_wheel</child><axis><xyz>0 0 1</xyz></axis></joint>
      <joint name="right_wheel_joint" type="revolute"><parent>chassis</parent><child>right_wheel</child><axis><xyz>0 0 1</xyz></axis></joint>
      <joint name="caster_joint" type="ball"><parent>chassis</parent><child>caster</child></joint>
      <joint name="lidar_joint" type="fixed"><parent>chassis</parent><child>lidar_link</child></joint>

      <plugin filename="gz-sim-diff-drive-system" name="gz::sim::systems::DiffDrive">
        <left_joint>left_wheel_joint</left_joint>
        <right_joint>right_wheel_joint</right_joint>
        <wheel_separation>0.24</wheel_separation>
        <wheel_radius>0.1</wheel_radius>
        <topic>/cmd_vel</topic>
        <odom_topic>/odom</odom_topic>
        <frame_id>odom</frame_id>
        <child_frame_id>chassis</child_frame_id>
        <publish_odom_tf>true</publish_odom_tf>
      </plugin>

      <plugin filename="gz-sim-pose-publisher-system" name="gz::sim::systems::PosePublisher">
        <publish_link_pose>true</publish_link_pose>
        <publish_sensor_pose>true</publish_sensor_pose>
        <publish_collision_pose>false</publish_collision_pose>
        <publish_visual_pose>false</publish_visual_pose>
        <publish_nested_model_pose>true</publish_nested_model_pose>
        <use_pose_vector_msg>true</use_pose_vector_msg>
        <static_publisher>true</static_publisher>
        <static_update_frequency>10</static_update_frequency>
      </plugin>
    </model>
  </world>
</sdf>