<?xml version="1.0"?>
<robot xmlns:xacro="http://www.ros.org/wiki/xacro" name="rescue_bot">

    <material name="blue"><color rgba="0 0 0.8 1"/></material>
    <material name="black"><color rgba="0 0 0 1"/></material>
    <material name="white"><color rgba="1 1 1 1"/></material>
    <link name="base_footprint"/>
    <joint name="base_joint" type="fixed">
        <parent link="base_footprint"/>
        <child link="base_link"/>
        <origin xyz="0 0 0.075" rpy="0 0 0"/>
    </joint>

    <link name="base_link">
        <visual>
            <geometry><box size="0.4 0.3 0.15"/></geometry>
            <material name="blue"/>
        </visual>
        <collision>
            <geometry><box size="0.4 0.3 0.15"/></geometry>
        </collision>
        <inertial>
            <mass value="5.0"/>
            <inertia ixx="0.046" ixy="0" ixz="0" iyy="0.076" iyz="0" izz="0.104"/>
        </inertial>
    </link>

    <link name="caster_wheel">
        <visual>
            <geometry><sphere radius="0.05"/></geometry>
            <material name="black"/>
        </visual>
        <collision>
            <geometry><sphere radius="0.05"/></geometry>
        </collision>
        <inertial>
            <mass value="0.5"/>
            <inertia ixx="0.0005" ixy="0" ixz="0" iyy="0.0005" iyz="0" izz="0.0005"/>
        </inertial>
    </link>
    <joint name="caster_joint" type="fixed">
        <parent link="base_link"/>
        <child link="caster_wheel"/>
        <origin xyz="0.15 0 -0.075" rpy="0 0 0"/>
    </joint>

    <xacro:macro name="wheel" params="prefix y_offset">
        <link name="${prefix}_wheel">
            <visual>
                <geometry><cylinder radius="0.1" length="0.04"/></geometry>
                <material name="black"/>
            </visual>
            <collision>
                <geometry><cylinder radius="0.1" length="0.04"/></geometry>
            </collision>
            <inertial>
                <mass value="1.0"/>
                <inertia ixx="0.0026" ixy="0" ixz="0" iyy="0.0026" iyz="0" izz="0.005"/>
            </inertial>
        </link>
        <joint name="${prefix}_wheel_joint" type="continuous">
            <parent link="base_link"/>
            <child link="${prefix}_wheel"/>
            <origin xyz="-0.1 ${y_offset} -0.025" rpy="-1.5708 0 0"/>
            <axis xyz="0 0 1"/>
        </joint>
    </xacro:macro>

    <xacro:wheel prefix="left" y_offset="0.17"/>
    <xacro:wheel prefix="right" y_offset="-0.17"/>

    <link name="laser_frame">
        <visual>
            <geometry><cylinder radius="0.05" length="0.04"/></geometry>
            <material name="black"/>
        </visual>
    </link>
    <joint name="laser_joint" type="fixed">
        <parent link="base_link"/>
        <child link="laser_frame"/>
        <origin xyz="0 0 0.095" rpy="0 0 0"/>
    </joint>

    <link name="camera_link">
        <visual>
            <geometry><box size="0.02 0.05 0.05"/></geometry>
            <material name="white"/>
        </visual>
    </link>
    <joint name="camera_joint" type="fixed">
        <parent link="base_link"/>
        <child link="camera_link"/>
        <origin xyz="0.2 0 0.05" rpy="0 0 0"/>
    </joint>

<gazebo>
        <plugin filename="gz-sim-diff-drive-system" name="gz::sim::systems::DiffDrive">
            <left_joint>left_wheel_joint</left_joint>
            <right_joint>right_wheel_joint</right_joint>
            <wheel_separation>0.34</wheel_separation>
            <wheel_radius>0.1</wheel_radius>
            <odom_publish_frequency>50</odom_publish_frequency>
            <topic>/cmd_vel</topic>
            <odom_topic>/odom</odom_topic>
            <frame_id>odom</frame_id>
	    <child_frame_id>base_footprint</child_frame_id>
        </plugin>
        <plugin filename="gz-sim-joint-state-publisher-system" name="gz::sim::systems::JointStatePublisher">
            <topic>joint_states</topic>
            <joint_name>left_wheel_joint</joint_name>
            <joint_name>right_wheel_joint</joint_name>
        </plugin>
    </gazebo>

    <gazebo reference="laser_frame">
        <sensor name="laser" type="gpu_lidar">
            <pose>0 0 0 0 0 0</pose>
            <always_on>true</always_on>
            <visualize>true</visualize>
            <update_rate>10</update_rate>
            <topic>/scan</topic>
            <gz_frame_id>laser_frame</gz_frame_id>
            <lidar>
                <scan>
                    <horizontal>
                        <samples>360</samples>
                        <resolution>1</resolution>
                        <min_angle>-3.14</min_angle>
                        <max_angle>3.14</max_angle>
                    </horizontal>
                </scan>
                <range>
                    <min>0.3</min>
                    <max>12.0</max>
                </range>
            </lidar>
        </sensor>
    </gazebo>

    <gazebo reference="camera_link">
        <sensor name="camera" type="camera">
            <always_on>true</always_on>
            <visualize>true</visualize>
            <update_rate>30.0</update_rate>
            <topic>/camera/image_raw</topic>
            <gz_frame_id>camera_link</gz_frame_id>
            <camera>
                <horizontal_fov>1.3962634</horizontal_fov>
                <image>
                    <width>800</width>
                    <height>800</height>
                    <format>R8G8B8</format>
                </image>
                <clip>
                    <near>0.02</near>
                    <far>300</far>
                </clip>
            </camera>
        </sensor>
    </gazebo>
</robot>
